Workbook

Sheet DB_PONTES_BA
A1: ID | B1: ANO | C1: EDITAL | D1: ESTADO | E1: DEPARTMENT | F1: PROJETO | G1: LOCALIZAÇÃO | H1: COMP_TOTAL_M | I1: GABARITO_M | J1: LARGURA_M | K1: TIPO_CONSTRUTIVA | L1: BUDGET | M1: T_DIAS | N1: P_C | O1: M_GUT
A2: 01 | B2: 2025 | C2: 002-2025 NºBB 1064672 | D2: BA | E2: SEINFRA-BA | F2: Ponte sobre Rio Inhambupe, BA-233 | G2: Sátiro Dias, Inhanbupe, BA | H2: 20 | I2: 1 | J2: 10 | K2: LP | L2: 1943002.4 | M2: 180 | N2: =L2/H2 -> 97150.118 | O2: =GUT!E2 -> 9.2
A3: 02 | B3: 2025 | C3: 003-2025 NºBB 1065686 | D3: BA | E3: SEINFRA-BA | F3: 02 Pontes em Cotegipe, BA | G3: BA-465 e BA-449, Cotegipe, BA | H3: 22 | I3: 3.37 | J3: 10 | K3: TML | L3: 1426937.8 | M3: 180 | N3: =L3/H3 -> 64860.807 | O3: =GUT!E8 -> 2.2
A4: 03 | B4: 2025 | C4: 005-2025 NºBB 1069824 | D4: BA | E4: SEINFRA-BA | F4: Ponte sobre o Rio das São João | G4: Caetité, BA | H4: 20 | I4: 3 | J4: 10 | K4: MET | L4: 2783939.7 | M4: 180 | N4: =L4/H4 -> 139196.98 | O4: =GUT!E14 -> 3.6
A5: 04 | B5: 2025 | C5: 007-2025 Nº1070008 | D5: BA | E5: SEINFRA-BA | F5: Ponte sobre o Riacho da Onça | G5: BA-601, Coribe, BA | H5: 30 | I5: 2.5 | J5: 10.2 | K5: MET | L5: 3534439.3 | M5: 240 | N5: =L5/H5 -> 117814.64 | O5: =GUT!E20 -> 2.6
A6: 05 | B6: 2025 | C6: 020-2025 Nº BB 1084814 (01) | D6: BA | E6: SEINFRA-BA | F6: 01/02 Pontes sobre o Riacho da Vereda | G6: BA-449 Km 49, Cotegipe, BA | H6: 30 | I6: 5.8 | J6: 11.5 | K6: TML | L6: =2729912.04+992508.92+27261.13+2124.72+74397.69+9364.31++(453491.4+42052.27+51526.35)*120/270 -> 4078711 | M6: 120 | N6: =L6/H6 -> 135957.03 | O6: =GUT!E26 -> 2.2
A7: 06 | B7: 2025 | C7: 020-2025 Nº BB 1084814 (02) | D7: BA | E7: SEINFRA-BA | F7: 02/02 Pontes sobre o Riacho da Vereda | G7: BA-449 Km 50, Cotegipe, BA | H7: 50 | I7: =1.65+7.15+1.4 -> 10.2 | J7: 10 | K7: MET | L7: =1632262.42+2293695.42+1085980.34+1751.75+51487.05+30489.32+(453491.4+42052.27+51526.35)*150/270 -> 5399594.1 | M7: 150 | N7: =L7/H7 -> 107991.88 | O7: =GUT!E32 -> 3.6
A8: 07 | B8: 2024 | C8: 023-2024 Nº BB 1059725 (01) | D8: BA | E8: SEINFRA-BA | F8: 01/03 Pontes sobre o Riacho Alegre | G8: BA-161, Muquém do São Francisco, BA | H8: 44 | M8: 210 | N8: =L8/H8 -> 0 | O8: =GUT!E38 -> 0
A9: 08 | B9: 2024 | C9: 023-2024 Nº BB 1059725 (02) | D9: BA | E9: SEINFRA-BA | F9: 02/03 Pontes sobre o Riacho Alegre | G9: BA-161, Muquém do São Francisco, BA | H9: 33 | N9: =L9/H9 -> 0
A10: 09 | B10: 2024 | C10: 023-2024 Nº BB 1059725 (03) | D10: BA | E10: SEINFRA-BA | F10: 03/03 Pontes sobre o Riacho Alegre | G10: BA-161, Muquém do São Francisco, BA | H10: 33 | N10: =L10/H10 -> 0
A11: 10 | B11: 2025 | C11: 023-2025 nº BB 1084872 | D11: BA | E11: SEINFRA-BA | F11: Ponte sobre o Rio da Itanhentinga | G11: BA-466, São José de Alcobaça, Alcobaça, BA | N11: =L11/H11 -> #DIV/0! | O11: =GUT!E44 -> 0
A12: 11 | B12: 2025 | C12: 024-2024 Nº BB 1060421 | D12: BA | E12: SEINFRA-BA | F12: Ponte sobre o Riacho da Vargem Grande | G12: BA-466, Tabocas do Brejo Velho, BA | H12: 30 | N12: =L12/H12 -> 0 | O12: =GUT!E50 -> 0
A13: 12 | B13: 2025 | C13: 025-2025 nº BB 1061034 | D13: BA | E13: SEINFRA-BA | F13: Ponte sobre o Rio Gavião | G13: BA-625, Caraíbas, BA | H13: 200 | N13: =L13/H13 -> 0 | O13: =GUT!E56 -> 0
A14: 13 | B14: 2025 | C14: 028-2025 - BB 1085144 | D14: BA | E14: SEINFRA-BA | F14: Ponte sobre o rio Inhambupe | G14: BA-084, Biritinga, BA | N14: =L14/H14 -> #DIV/0! | O14: =GUT!E62 -> 0

Sheet GUT
A1: Impacto / Indicador | B1: Gravidade (G) | C1: Urgência (U) | D1: Tendência (T) | E1: Total (GUT) | G1: Escala de Pontuação (1 a 5) Gravidade: 1 (Dano mínimo) a 5 (Dano ambiental ou social irreversível). Urgência: 1 (Pode esperar) a 5 (Ação imediata necessária no projeto). Tendência: 1 (Estável/Melhora) a 5 (Piora rápida se não houver intervenção). Procedimento de Avaliação O objetivo deste procedimento é padronizar a nota atribuída aos projetos, garantindo que a análise de sustentabilidade seja técnica e comparável. Inventário de Aspectos: Liste os principais elementos do projeto que geram impacto, como o volume de concreto/aço (carbono incorporado), a necessidade de desvio de cursos d'água e a integração com a comunidade local. Atribuição de Notas: Reúna a equipe técnica para pontuar cada indicador de 1 a 5. A gravidade deve considerar o ciclo de vida total da ponte, a urgência deve focar no cronograma de decisão do projeto e a tendência deve avaliar o agravamento de riscos ambientais futuros. Cálculo e Ranking: Multiplique os três fatores para obter o índice de prioridade. Projetos ou indicadores com pontuação próxima a 125 exigem revisão imediata das soluções de engenharia para conformidade com metas de sustentabilidade. Proposição de Mitigação: Para cada item com GUT elevado, descreva uma medida mitigadora curta, como a substituição de materiais por alternativas de menor impacto ou o ajuste da geometria para preservar a vegetação ciliar.
A2: 002-2025 NºBB 1064672 | E2: =AVERAGE(E3:E7) -> 9.2
A3: Pegada de Carbono (Materiais) | B3: 2 | C3: 1 | D3: 1 | E3: =B3*C3*D3 -> 2
A4: Interferência no Ecossistema Local | B4: 3 | C4: 2 | D4: 1 | E4: =B4*C4*D4 -> 6
A5: Resiliência Climática (Cheias/Eventos) | B5: 3 | C5: 3 | D5: 4 | E5: =B5*C5*D5 -> 36
A6: Manutenibilidade e Vida Útil | B6: 1 | C6: 1 | D6: 1 | E6: =B6*C6*D6 -> 1
A7: Segurança e Acessibilidade Social | B7: 1 | C7: 1 | D7: 1 | E7: =B7*C7*D7 -> 1
A8: 003-2025 NºBB 1065686 (01) | E8: =AVERAGE(E9:E13) -> 2.2
A9: Pegada de Carbono (Materiais) | B9: 2 | C9: 1 | D9: 1 | E9: =B9*C9*D9 -> 2
A10: Interferência no Ecossistema Local | B10: 3 | C10: 2 | D10: 1 | E10: =B10*C10*D10 -> 6
A11: Resiliência Climática (Cheias/Eventos) | B11: 1 | C11: 1 | D11: 1 | E11: =B11*C11*D11 -> 1
A12: Manutenibilidade e Vida Útil | B12: 1 | C12: 1 | D12: 1 | E12: =B12*C12*D12 -> 1
A13: Segurança e Acessibilidade Social | B13: 1 | C13: 1 | D13: 1 | E13: =B13*C13*D13 -> 1
A14: 005-2025 NºBB 1069824 | E14: =AVERAGE(E15:E19) -> 3.6
A15: Pegada de Carbono (Materiais) | B15: 3 | C15: 2 | D15: 1 | E15: =B15*C15*D15 -> 6
A16: Interferência no Ecossistema Local | B16: 3 | C16: 3 | D16: 1 | E16: =B16*C16*D16 -> 9
A17: Resiliência Climática (Cheias/Eventos) | B17: 1 | C17: 1 | D17: 1 | E17: =B17*C17*D17 -> 1
A18: Manutenibilidade e Vida Útil | B18: 1 | C18: 1 | D18: 1 | E18: =B18*C18*D18 -> 1
A19: Segurança e Acessibilidade Social | B19: 1 | C19: 1 | D19: 1 | E19: =B19*C19*D19 -> 1
A20: 007-2025 Nº1070008 | E20: =AVERAGE(E21:E25) -> 2.6
A21: Pegada de Carbono (Materiais) | B21: 3 | C21: 2 | D21: 1 | E21: =B21*C21*D21 -> 6
A22: Interferência no Ecossistema Local | B22: 2 | C22: 2 | D22: 1 | E22: =B22*C22*D22 -> 4
A23: Resiliência Climática (Cheias/Eventos) | B23: 1 | C23: 1 | D23: 1 | E23: =B23*C23*D23 -> 1
A24: Manutenibilidade e Vida Útil | B24: 1 | C24: 1 | D24: 1 | E24: =B24*C24*D24 -> 1
A25: Segurança e Acessibilidade Social | B25: 1 | C25: 1 | D25: 1 | E25: =B25*C25*D25 -> 1
A26: 020-2025 Nº BB 1084814 (01) | E26: =AVERAGE(E27:E31) -> 2.2
A27: Pegada de Carbono (Materiais) | B27: 2 | C27: 1 | D27: 1 | E27: =B27*C27*D27 -> 2
A28: Interferência no Ecossistema Local | B28: 3 | C28: 2 | D28: 1 | E28: =B28*C28*D28 -> 6
A29: Resiliência Climática (Cheias/Eventos) | B29: 1 | C29: 1 | D29: 1 | E29: =B29*C29*D29 -> 1
A30: Manutenibilidade e Vida Útil | B30: 1 | C30: 1 | D30: 1 | E30: =B30*C30*D30 -> 1
A31: Segurança e Acessibilidade Social | B31: 1 | C31: 1 | D31: 1 | E31: =B31*C31*D31 -> 1
A32: 020-2025 Nº BB 1084814 (02) | E32: =AVERAGE(E33:E37) -> 3.6
A33: Pegada de Carbono (Materiais) | B33: 3 | C33: 2 | D33: 1 | E33: =B33*C33*D33 -> 6
A34: Interferência no Ecossistema Local | B34: 3 | C34: 3 | D34: 1 | E34: =B34*C34*D34 -> 9
A35: Resiliência Climática (Cheias/Eventos) | B35: 1 | C35: 1 | D35: 1 | E35: =B35*C35*D35 -> 1
A36: Manutenibilidade e Vida Útil | B36: 1 | C36: 1 | D36: 1 | E36: =B36*C36*D36 -> 1
A37: Segurança e Acessibilidade Social | B37: 1 | C37: 1 | D37: 1 | E37: =B37*C37*D37 -> 1
A38: 023-2024 Nº BB 1059725 | E38: =AVERAGE(E39:E43) -> 0
A39: Pegada de Carbono (Materiais) | E39: =B39*C39*D39 -> 0
A40: Interferência no Ecossistema Local | E40: =B40*C40*D40 -> 0
...
